Workbook

Sheet Cover
A1: NIFTY 50 Equity Derivatives – Futures Analysis
A2: Prepared by: Tushar Varkhede (MBA)
A3: =TEXT(Summary!B2,"dd-mmm-yyyy")&" to "&TEXT(Summary!B3,"dd-mmm-yyyy")&" | NSE NIFTY Index Futures" -> 01-Jan-2025 to 31-Dec-2025 | NSE NIFTY Index Futures
A5: Field | B5: Value
A6: Actual data period | B6: =TEXT(Summary!B2,"dd-mmm-yyyy")&" to "&TEXT(Summary!B3,"dd-mmm-yyyy") -> 01-Jan-2025 to 31-Dec-2025
A7: Source | B7: NSE NIFTY Index Futures CSV supplied by user
A8: Objective | B8: Describe how NIFTY index futures traded in 2025 – liquidity, basis (futures vs index), open interest and price–OI behaviour – and test whether simple price–OI labels carry any next-day information.
A9: Key questions | B9: 1) Where does trading concentrate across contracts? 2) How does basis behave across tenor, time to expiry and month? 3) How does open interest roll between contracts? 4) Do price–OI labels predict the next day's move?
A10: Scope | B10: Futures price, basis, contracts, open interest and price–OI interpretation
A11: Limitation | B11: Options data is not included; this is a futures-only study. No interest-rate or dividend data, so carry is measured but not benchmarked.
A12: Method note | B12: Exact duplicate rows removed; repeated headers and blank rows excluded. Derived columns (basis, returns, OI interpretation) and all summary tables are live formulas on Cleaned_Futures_Data.
A13: Definitions | B13: Basis = futures close − underlying value (index points). Basis % = basis ÷ underlying. Annualised basis = Basis % × 365 ÷ days to expiry. Near month = contract with the earliest expiry on that date (Series Rank 1).
A14: OI interpretation rule | B14: Compared with the previous row of the same contract: price up & OI up = Long buildup; price down & OI up = Short buildup; price up & OI down = Short covering; price down & OI down = Long unwinding.
A15: Sheet guide | B15: Executive_Summary – overview and headline results | Scope_and_Approach – what was studied and how | Findings – detailed findings and data notes | Dashboard – charts and KPIs | Cleaned_Futures_Data – data plus derived/helper columns (blue headers V–AB are analysis helpers) | Summary, Monthly_Summary, Expiry_Summary, OI_Interpretation_Summary – tables | Basis_Analysis – basis by tenor, expiry proximity and OI rollover (holds the editable inputs) | NearMonth_Daily – daily near-month series | Conclusion – answers, limitations and next steps
A16: Editable inputs | B16: Basis_Analysis: expiry-week cutoff (B3), days-to-expiry bucket bounds and series rank bounds (blue text).

Sheet Executive_Summary
A1: Executive Summary
A2: NIFTY 50 Equity Derivatives – Futures Analysis 2025 | Prepared by Tushar Varkhede (MBA)
A4: Executive summary
A5: Overview | B5: ="This project analyses NIFTY 50 index futures from "&TEXT(Summary!B2,"dd-mmm-yyyy")&" to "&TEXT(Summary!B3,"dd-mmm-yyyy")&" using the NSE NIFTY futures file supplied for the project: "&TEXT(Summary!B4,"#,##0")&" contract-day records across "&Summary!B5&" trading dates and "&Summary!B6&" expiries, with "&TEXT(Summary!B11/1000000,"0.0")&" mn contracts traded (turnover about ₹"&TEXT(Summary!B12/10000000,"0.0")&" lakh crore). It asks where trading concentrates, how the futures-to-index basis behaves, how open interest rolls between contracts, and whether simple price–open interest labels say anything about the next day." -> This project analyses NIFTY 50 index futures from 01-Jan-2025 to 31-Dec-2025 using the NSE NIFTY futures file supplied for the project: 755 contract-day records across 249 trading dates and 16 expiries, with 29.9 mn contracts traded (turnover about ₹48.3 lakh crore). It asks where trading concentrates, how the futures-to-index basis behaves, how open interest rolls between contracts, and whether simple price–open interest labels say anything about the next day.
A7: Headline results
A8: 1. Liquidity | B8: ="The near-month contract accounts for "&TEXT(Basis_Analysis!F18,"0.0%")&" of all contracts traded ("&TEXT(Basis_Analysis!F19,"0.0%")&" next month, "&TEXT(Basis_Analysis!F20,"0.0%")&" far month), so the analysis focuses on the near-month series." -> The near-month contract accounts for 79.3% of all contracts traded (18.3% next month, 2.4% far month), so the analysis focuses on the near-month series.
A9: 2. Basis | B9: ="Near-month futures traded at an average premium of about "&TEXT(Basis_Analysis!H18,"0")&" points ("&TEXT(Basis_Analysis!I18,"0.00%")&") to the index. The premium is larger for longer tenors ("&TEXT(Basis_Analysis!H19,"0")&" and "&TEXT(Basis_Analysis!H20,"0")&" points for next and far month) and narrows to about "&TEXT(Basis_Analysis!E8,"0.0")&" points on expiry day. Annualised, the near-month premium is about "&TEXT(Basis_Analysis!B4,"0.0%")&", the pattern expected from cost-of-carry pricing." -> Near-month futures traded at an average premium of about 68 points (0.28%) to the index. The premium is larger for longer tenors (202 and 340 points for next and far month) and narrows to about -3.5 points on expiry day. Annualised, the near-month premium is about 6.9%, the pattern expected from cost-of-carry pricing.
A10: 3. Open-interest rollover | B10: ="Open interest moves from the near to the next month mainly in the final week: the near-month share of near+next open interest falls from "&TEXT(Basis_Analysis!J13,"0%")&" at 21+ days to expiry to "&TEXT(Basis_Analysis!J9,"0%")&" at 1–5 days and "&TEXT(Basis_Analysis!J8,"0%")&" on expiry day." -> Open interest moves from the near to the next month mainly in the final week: the near-month share of near+next open interest falls from 91% at 21+ days to expiry to 52% at 1–5 days and 23% on expiry day.
A11: 4. Price–OI labels | B11: ="Buildup labels (long or short) made up "&TEXT(OI_Interpretation_Summary!C2+OI_Interpretation_Summary!C3,"0%")&" of records. Outside expiry week, the next day's close was higher after only "&TEXT(MIN(OI_Interpretation_Summary!E13:E16),"0%")&" to "&TEXT(MAX(OI_Interpretation_Summary!E13:E16),"0%")&" of labelled days, so the labels did not give a reliable next-day signal. In expiry week "&TEXT(OI_Interpretation_Summary!B22,"0%")&" of classified near-month days showed falling open interest, which is contract expiry rather than a change in view." -> Buildup labels (long or short) made up 72% of records. Outside expiry week, the next day's close was higher after only 40% to 51% of labelled days, so the labels did not give a reliable next-day signal. In expiry week 100% of classified near-month days showed falling open interest, which is contract expiry rather than a change in view.
A12: Bottom line | B12: In 2025 NIFTY futures behaved as cost-of-carry pricing and an expiry-driven roll cycle would suggest. The price–OI labels are useful for describing what happened on a given day but should not be treated as a trading signal on this evidence.

Sheet Scope_and_Approach
A1: Scope and Approach
A2: NIFTY 50 Equity Derivatives – Futures Analysis 2025 | Prepared by Tushar Varkhede (MBA)
A4: Scope
A5: In scope | B5: ="NIFTY 50 index futures, all listed expiries, daily data from "&TEXT(Summary!B2,"dd-mmm-yyyy")&" to "&TEXT(Summary!B3,"dd-mmm-yyyy")&": prices, contracts traded, turnover, open interest and the underlying index value." -> NIFTY 50 index futures, all listed expiries, daily data from 01-Jan-2025 to 31-Dec-2025: prices, contracts traded, turnover, open interest and the underlying index value.
A6: Out of scope | B6: Options, other indices and stock futures, intraday data, interest-rate and dividend data, and any trading-strategy test with costs.
A7: Data source | B7: NSE NIFTY Index Futures CSV supplied by the user. Exact duplicate rows were removed and repeated headers and blank rows excluded. The data was not re-verified against NSE directly.
A8: Data gaps | B8: ="Of the "&TEXT(Summary!B4,"#,##0")&" records, "&Findings!D19&" are no-trade rows, "&Findings!D20&" have prices but no index value (basis left blank) and "&Findings!D21&" cannot be classified for price–OI direction (the first observation of each expiry or a no-trade row without prior price/OI inputs). They are kept in the data but excluded from averages." -> Of the 755 records, 8 are no-trade rows, 15 have prices but no index value (basis left blank) and 24 cannot be classified for price–OI direction (the first observation of each expiry or a no-trade row without prior price/OI inputs). They are kept in the data but excluded from averages.
A10: Approach
A11: Step 1 – Prepare | B11: Add derived measures as live formulas on the cleaned data: basis (futures close minus index), basis %, days to expiry, daily price and open-interest changes, and the price–OI label.
A12: Step 2 – Near month | B12: Rank the listed expiries on each date. Rank 1 is the near-month contract and is used for like-for-like comparisons, because averaging across tenors mixes different basis levels.
A13: Step 3 – Basis | B13: Measure basis by contract series, by days to expiry and by month, and annualise it to get the carry rate implied by futures prices.
A14: Step 4 – Rollover | B14: Compare near- and next-month open interest as expiry approaches to see when positions roll.
A15: Step 5 – OI interpretation | B15: Label each day long buildup, short buildup, short covering or long unwinding from the direction of price and open interest against the previous day for the same contract.
A16: Step 6 – Signal test | B16: ="Outside expiry week (last "&Basis_Analysis!B3&" days to expiry excluded, because open interest falls mechanically then), test whether each label is followed by a higher close the next day." -> Outside expiry week (last 5 days to expiry excluded, because open interest falls mechanically then), test whether each label is followed by a higher close the next day.
A17: Step 7 – Present | B17: Summarise in the Findings sheet, dashboard charts and summary tables. Every figure is formula-linked to the cleaned data, so it updates if the data or inputs change.

Sheet Findings
A1: Key Findings
A2: Figures are formula-linked to the analysis sheets and update if the data or inputs change.
A4: # | B4: Theme | C4: Finding | D4: Evidence
A5: 1 | B5: Liquidity concentration | C5: ="The near-month contract carries "&TEXT(Basis_Analysis!F18,"0.0%")&" of all contracts traded ("&TEXT(Basis_Analysis!F19,"0.0%")&" next month, "&TEXT(Basis_Analysis!F20,"0.0%")&" far month). Price, basis and OI behaviour is therefore best read on the near-month series, which is what the near-month (NM) columns and charts use." -> The near-month contract carries 79.3% of all contracts traded (18.3% next month, 2.4% far month). Price, basis and OI behaviour is therefore best read on the near-month series, which is what the near-month (NM) columns and charts use. | D5: Basis_Analysis §2
A6: 2 | B6: Basis and tenor | C6: ="Basis widens with tenor: about "&TEXT(Basis_Analysis!H18,"0")&" pts (near), "&TEXT(Basis_Analysis!H19,"0")&" pts (next) and "&TEXT(Basis_Analysis!H20,"0")&" pts (far), or "&TEXT(Basis_Analysis!I18,"0.00%")&", "&TEXT(Basis_Analysis!I19,"0.00%")&" and "&TEXT(Basis_Analysis!I20,"0.00%")&" of the index. This is the pattern expected from cost-of-carry pricing. The all-series average of "&TEXT(Summary!B8,"0")&" pts on the Summary sheet blends these tenors and overstates the typical near-month basis." -> Basis widens with tenor: about 68 pts (near), 202 pts (next) and 340 pts (far), or 0.28%, 0.82% and 1.38% of the index. This is the pattern expected from cost-of-carry pricing. The all-series average of 203 pts on the Summary sheet blends these tenors and overstates the typical near-month basis. | D6: Basis_Analysis §2; Summary
A7: 3 | B7: Basis decay into expiry | C7: ="Near-month basis averages "&TEXT(Basis_Analysis!E13,"0")&" pts with 21+ days to expiry, "&TEXT(Basis_Analysis!E11,"0")&" pts at 11–15 days, "&TEXT(Basis_Analysis!E9,"0")&" pts in the last 1–5 days and "&TEXT(Basis_Analysis!E8,"0.0")&" pts on expiry day: the futures price converges on the index as expiry approaches." -> Near-month basis averages 109 pts with 21+ days to expiry, 70 pts at 11–15 days, 27 pts in the last 1–5 days and -3.5 pts on expiry day: the futures price converges on the index as expiry approaches. | D7: Basis_Analysis §1; Dashboard
A8: 4 | B8: Implied carry | C8: ="For near-month contracts outside expiry week, the annualised basis averages "&TEXT(Basis_Analysis!B4,"0.0%")&". This is the carry rate implied by futures prices. It has not been compared with a money-market rate or dividend yield because no such data was supplied, so mispricing cannot be concluded from this workbook." -> For near-month contracts outside expiry week, the annualised basis averages 6.9%. This is the carry rate implied by futures prices. It has not been compared with a money-market rate or dividend yield because no such data was supplied, so mispricing cannot be concluded from this workbook. | D8: Basis_Analysis B4
A9: 5 | B9: Open-interest rollover | C9: ="Open interest rolls from near to next month mostly in the final week. Near-month share of (near + next) OI is "&TEXT(Basis_Analysis!J13,"0%")&" at 21+ days, "&TEXT(Basis_Analysis!J10,"0%")&" at 6–10 days, "&TEXT(Basis_Analysis!J9,"0%")&" at 1–5 days and "&TEXT(Basis_Analysis!J8,"0%")&" on expiry day." -> Open interest rolls from near to next month mostly in the final week. Near-month share of (near + next) OI is 91% at 21+ days, 78% at 6–10 days, 52% at 1–5 days and 23% on expiry day. | D9: Basis_Analysis §1; Dashboard
A10: 6 | B10: Basis over the year | C10: ="Average near-month basis was about "&TEXT(AVERAGE(Monthly_Summary!I2:I9),"0")&" pts in Jan–Aug versus "&TEXT(AVERAGE(Monthly_Summary!I10:I13),"0")&" pts in Sep–Dec. The data cannot say why (rates, dividends, positioning and the change in expiry dates visible in the data from Sep-2025 are all candidates); it would need extra inputs to test." -> Average near-month basis was about 58 pts in Jan–Aug versus 88 pts in Sep–Dec. The data cannot say why (rates, dividends, positioning and the change in expiry dates visible in the data from Sep-2025 are all candidates); it would need extra inputs to test. | D10: Monthly_Summary col I; Dashboard
A11: 7 | B11: Volume trend | C11: ="January was the busiest month with "&TEXT(Monthly_Summary!C2/1000000,"0.0")&" mn contracts, about "&TEXT(Monthly_Summary!C2/AVERAGE(Monthly_Summary!C3:C13),"0.0")&"x the Feb–Dec monthly average of "&TEXT(AVERAGE(Monthly_Summary!C3:C13)/1000000,"0.0")&" mn. The busiest single near-month day was "&TEXT(INDEX(NearMonth_Daily!A2:A250,MATCH(MAX(NearMonth_Daily!G2:G250),NearMonth_Daily!G2:G250,0)),"dd-mmm-yyyy")&" ("&TEXT(MAX(NearMonth_Daily!G2:G250),"#,##0")&" contracts)." -> January was the busiest month with 6.0 mn contracts, about 2.8x the Feb–Dec monthly average of 2.2 mn. The busiest single near-month day was 21-Jan-2025 (388,434 contracts). | D11: Monthly_Summary; NearMonth_Daily
A12: 8 | B12: Peak open interest | C12: ="Near-month open interest peaked at "&TEXT(MAX(NearMonth_Daily!H2:H250)/1000000,"0.0")&" mn contracts on "&TEXT(INDEX(NearMonth_Daily!A2:A250,MATCH(MAX(NearMonth_Daily!H2:H250),NearMonth_Daily!H2:H250,0)),"dd-mmm-yyyy")&"." -> Near-month open interest peaked at 18.5 mn contracts on 07-Nov-2025. | D12: NearMonth_Daily; Dashboard
A13: 9 | B13: OI classification mix | C13: ="Short buildup ("&TEXT(OI_Interpretation_Summary!C2,"0%")&") and long buildup ("&TEXT(OI_Interpretation_Summary!C3,"0%")&") were the most common labels, together "&TEXT(OI_Interpretation_Summary!C2+OI_Interpretation_Summary!C3,"0%")&" of records; short covering and long unwinding made up "&TEXT(OI_Interpretation_Summary!C4+OI_Interpretation_Summary!C5,"0%")&". OI rose on most days, consistent with positions building up over each contract's life before expiry." -> Short buildup (41%) and long buildup (32%) were the most common labels, together 72% of records; short covering and long unwinding made up 24%. OI rose on most days, consistent with positions building up over each contract's life before expiry. | D13: OI_Interpretation_Summary
A14: 10 | B14: Expiry-week distortion | C14: ="In expiry week, "&TEXT(OI_Interpretation_Summary!B22,"0%")&" of classified near-month days are labelled long unwinding or short covering. That is mainly contracts expiring and OI rolling to the next month, not traders changing view, so expiry-week labels should not be read as sentiment." -> In expiry week, 100% of classified near-month days are labelled long unwinding or short covering. That is mainly contracts expiring and OI rolling to the next month, not traders changing view, so expiry-week labels should not be read as sentiment. | D14: OI_Interpretation_Summary
A15: 11 | B15: Do the labels predict? | C15: ="Outside expiry week, the close was higher the next day after only "&TEXT(MIN(OI_Interpretation_Summary!E13:E16),"0%")&" to "&TEXT(MAX(OI_Interpretation_Summary!E13:E16),"0%")&" of labelled days across the four labels (all labels: "&TEXT(OI_Interpretation_Summary!E17,"0%")&"; "&TEXT(MIN(OI_Interpretation_Summary!B13:B16),"0")&" to "&TEXT(MAX(OI_Interpretation_Summary!B13:B16),"0")&" observations each). The labels describe the day; in this sample they do not give a reliable next-day signal." -> Outside expiry week, the close was higher the next day after only 40% to 51% of labelled days across the four labels (all labels: 46%; 25 to 67 observations each). The labels describe the day; in this sample they do not give a reliable next-day signal. | D15: OI_Interpretation_Summary
A17: Limitations and data notes
A18: # | B18: Topic | C18: Detail | D18: Count / value
A19: 1 | B19: No-trade rows | C19: Contract listed but with no prices, volume or OI on that date; kept in the data but excluded from averages. | D19: =COUNTBLANK(Cleaned_Futures_Data!$G$2:$G$756) -> 8
A20: 2 | B20: Missing underlying | C20: Rows that have prices but no index value in the source file, so basis cannot be computed. | D20: =COUNT(Cleaned_Futures_Data!$G$2:$G$756)-COUNT(Cleaned_Futures_Data!$N$2:$N$756) -> 15
A21: 3 | B21: Not classified | C21: Rows with no previous-day price/OI for the same contract (first observation of each expiry or a no-trade row lacking prior price/OI inputs). | D21: =COUNTIF(Cleaned_Futures_Data!$U$2:$U$756,"Not classified") -> 24
A22: 4 | B22: Neutral | C22: Close price exactly unchanged, so no price direction to label. | D22: =COUNTIF(Cleaned_Futures_Data!$U$2:$U$756,"Neutral") -> 1
A23: 5 | B23: Partial expiries | C23: Expiries listed before 01-Jan-2025 or running past 31-Dec-2025 are only partly observed (see Expiry_Summary). | D23: =COUNTIF(Expiry_Summary!K2:K17,"Partial*") -> 6
A24: 6 | B24: Futures only | C24: No options data, interest-rate or dividend data was used, so carry/mispricing and put-call analysis are out of scope.
A25: 7 | B25: Source not re-verified | C25: Data is the NSE-format CSV supplied by the user; it was cleaned (exact duplicates removed) but not reconciled to NSE directly.
A26: 8 | B26: Units | C26: Basis % is stored as a fraction (shown as %). Close Return % and OI Change % are in percentage points. Turnover is in ₹ lakhs.

Sheet Dashboard
A1: NIFTY Futures Dashboard
A3: Key metric | B3: Value
A4: Trading dates | B4: =Summary!B5 -> 249
A5: Contract-day records | B5: =Summary!B4 -> 755
A6: Expiries in data | B6: =Summary!B6 -> 16
A7: Total contracts (mn) | B7: =Summary!B11/1000000 -> 29.854788
A8: Total turnover (₹ lakh crore) | B8: =Summary!B12/10000000 -> 48.299874
A9: Near-month share of contracts | B9: =Summary!B18 -> 0.79259293
A10: Near-month avg basis (pts) | B10: =Summary!B19 -> 68.065779
A11: Near-month annualised basis | B11: =Summary!B21 -> 0.069360256
A12: Peak near-month OI (mn) | B12: =Summary!B22/1000000 -> 18.5475
A13: Peak OI date | B13: =Summary!B23 -> 45968
A15: Conclusions: see the Findings sheet.
A16: NM = near month (earliest listed expiry on each date).

Sheet Summary
A1: Metric | B1: Value
A2: Data start | B2: =MIN(Cleaned_Futures_Data!$B$2:$B$756) -> 45658
A3: Data end | B3: =MAX(Cleaned_Futures_Data!$B$2:$B$756) -> 46022
A4: Cleaned records | B4: =COUNTA(Cleaned_Futures_Data!$A$2:$A$756) -> 755
A5: Unique trading dates | B5: =SUMPRODUCT(1/COUNTIF(Cleaned_Futures_Data!$B$2:$B$756,Cleaned_Futures_Data!$B$2:$B$756)) -> 249
A6: Unique expiries | B6: =SUMPRODUCT(1/COUNTIF(Cleaned_Futures_Data!$C$2:$C$756,Cleaned_Futures_Data!$C$2:$C$756)) -> 16
A7: Valid basis records | B7: =COUNT(Cleaned_Futures_Data!$O$2:$O$756) -> 732
A8: Basis average | B8: =AVERAGE(Cleaned_Futures_Data!$O$2:$O$756) -> 203.47425
A9: Basis minimum | B9: =MIN(Cleaned_Futures_Data!$O$2:$O$756) -> -19.4
A10: Basis maximum | B10: =MAX(Cleaned_Futures_Data!$O$2:$O$756) -> 537.7
A11: Total contracts | B11: =SUM(Cleaned_Futures_Data!$J$2:$J$756) -> 29854788
A12: Total turnover (₹ Lakhs) | B12: =SUM(Cleaned_Futures_Data!$K$2:$K$756) -> 4.8299874e+08
A13: OI classified records | B13: =COUNTA(Cleaned_Futures_Data!$U$2:$U$756)-COUNTIF(Cleaned_Futures_Data!$U$2:$U$756,"Not classified") -> 731
A15: Near-month (front-series) metrics
A16: Metric | B16: Value
A17: Near-month observations | B17: =COUNTIF(Cleaned_Futures_Data!$W$2:$W$756,1) -> 249
A18: Near-month share of contracts | B18: =Basis_Analysis!F18 -> 0.79259293
A19: Near-month basis average (pts) | B19: =AVERAGEIFS(Cleaned_Futures_Data!$O$2:$O$756,Cleaned_Futures_Data!$W$2:$W$756,1) -> 68.065779
A20: Near-month basis average (%) | B20: =AVERAGEIFS(Cleaned_Futures_Data!$P$2:$P$756,Cleaned_Futures_Data!$W$2:$W$756,1) -> 0.0027611099
A21: Near-month annualised basis (DTE > cutoff) | B21: =Basis_Analysis!B4 -> 0.069360256
A22: Peak near-month open interest | B22: =MAX(NearMonth_Daily!$H$2:$H$250) -> 18547500
A23: Peak open interest date | B23: =INDEX(NearMonth_Daily!$A$2:$A$250,MATCH(MAX(NearMonth_Daily!$H$2:$H$250),NearMonth_Daily!$H$2:$H$250,0)) -> 45968
A25: Basis average above (row 8) blends near, next and far contracts. Use the near-month figures for a like-for-like view.

Sheet Monthly_Summary
A1: Month | B1: Observations | C1: Total_Contracts | D1: Avg_OI | E1: Avg_Basis | F1: Turnover_Lakhs | G1: NM_Contracts | H1: NM_Share_of_Contracts | I1: NM_Avg_Basis | J1: NM_Avg_Basis_% | K1: NM_Avg_OI
A2: 2025-01 | B2: =COUNTIFS(Cleaned_Futures_Data!$V$2:$V$756,$A2) -> 70 | C2: =SUMIFS(Cleaned_Futures_Data!$J$2:$J$756,Cleaned_Futures_Data!$V$2:$V$756,$A2) -> 6009928 | D2: =AVERAGEIFS(Cleaned_Futures_Data!$L$2:$L$756,Cleaned_Futures_Data!$V$2:$V$756,$A2) -> 5801928.6 | E2: =AVERAGEIFS(Cleaned_Futures_Data!$O$2:$O$756,Cleaned_Futures_Data!$V$2:$V$756,$A2) -> 208.81594 | F2: =SUMIFS(Cleaned_Futures_Data!$K$2:$K$756,Cleaned_Futures_Data!$V$2:$V$756,$A2) -> 42926850 | G2: =SUMIFS(Cleaned_Futures_Data!$J$2:$J$756,Cleaned_Futures_Data!$V$2:$V$756,$A2,Cleaned_Futures_Data!$W$2:$W$756,1) -> 5440422 | H2: =G2/C2 -> 0.90523913 | I2: =AVERAGEIFS(Cleaned_Futures_Data!$O$2:$O$756,Cleaned_Futures_Data!$V$2:$V$756,$A2,Cleaned_Futures_Data!$W$2:$W$756,1) -> 67.136957 | J2: =AVERAGEIFS(Cleaned_Futures_Data!$P$2:$P$756,Cleaned_Futures_Data!$V$2:$V$756,$A2,Cleaned_Futures_Data!$W$2:$W$756,1) -> 0.0028587268 | K2: =AVERAGEIFS(Cleaned_Futures_Data!$L$2:$L$756,Cleaned_Futures_Data!$V$2:$V$756,$A2,Cleaned_Futures_Data!$W$2:$W$756,1) -> 12654868
A3: 2025-02 | B3: =COUNTIFS(Cleaned_Futures_Data!$V$2:$V$756,$A3) -> 61 | C3: =SUMIFS(Cleaned_Futures_Data!$J$2:$J$756,Cleaned_Futures_Data!$V$2:$V$756,$A3) -> 2326946 | D3: =AVERAGEIFS(Cleaned_Futures_Data!$L$2:$L$756,Cleaned_Futures_Data!$V$2:$V$756,$A3) -> 6342351.2 | E3: =AVERAGEIFS(Cleaned_Futures_Data!$O$2:$O$756,Cleaned_Futures_Data!$V$2:$V$756,$A3) -> 203.67982 | F3: =SUMIFS(Cleaned_Futures_Data!$K$2:$K$756,Cleaned_Futures_Data!$V$2:$V$756,$A3) -> 40274515 | G3: =SUMIFS(Cleaned_Futures_Data!$J$2:$J$756,Cleaned_Futures_Data!$V$2:$V$756,$A3,Cleaned_Futures_Data!$W$2:$W$756,1) -> 1876281 | H3: =G3/C3 -> 0.80632769 | I3: =AVERAGEIFS(Cleaned_Futures_Data!$O$2:$O$756,Cleaned_Futures_Data!$V$2:$V$756,$A3,Cleaned_Futures_Data!$W$2:$W$756,1) -> 62.421053 | J3: =AVERAGEIFS(Cleaned_Futures_Data!$P$2:$P$756,Cleaned_Futures_Data!$V$2:$V$756,$A3,Cleaned_Futures_Data!$W$2:$W$756,1) -> 0.0027107936 | K3: =AVERAGEIFS(Cleaned_Futures_Data!$L$2:$L$756,Cleaned_Futures_Data!$V$2:$V$756,$A3,Cleaned_Futures_Data!$W$2:$W$756,1) -> 15540165
A4: 2025-03 | B4: =COUNTIFS(Cleaned_Futures_Data!$V$2:$V$756,$A4) -> 58 | C4: =SUMIFS(Cleaned_Futures_Data!$J$2:$J$756,Cleaned_Futures_Data!$V$2:$V$756,$A4) -> 2149492 | D4: =AVERAGEIFS(Cleaned_Futures_Data!$L$2:$L$756,Cleaned_Futures_Data!$V$2:$V$756,$A4) -> 6439617.1 | E4: =AVERAGEIFS(Cleaned_Futures_Data!$O$2:$O$756,Cleaned_Futures_Data!$V$2:$V$756,$A4) -> 199.35093 | F4: =SUMIFS(Cleaned_Futures_Data!$K$2:$K$756,Cleaned_Futures_Data!$V$2:$V$756,$A4) -> 37214609 | G4: =SUMIFS(Cleaned_Futures_Data!$J$2:$J$756,Cleaned_Futures_Data!$V$2:$V$756,$A4,Cleaned_Futures_Data!$W$2:$W$756,1) -> 1613022 | H4: =G4/C4 -> 0.7504201 | I4: =AVERAGEIFS(Cleaned_Futures_Data!$O$2:$O$756,Cleaned_Futures_Data!$V$2:$V$756,$A4,Cleaned_Futures_Data!$W$2:$W$756,1) -> 61.708333 | J4: =AVERAGEIFS(Cleaned_Futures_Data!$P$2:$P$756,Cleaned_Futures_Data!$V$2:$V$756,$A4,Cleaned_Futures_Data!$W$2:$W$756,1) -> 0.0027337817 | K4: =AVERAGEIFS(Cleaned_Futures_Data!$L$2:$L$756,Cleaned_Futures_Data!$V$2:$V$756,$A4,Cleaned_Futures_Data!$W$2:$W$756,1) -> 15222375
A5: 2025-04 | B5: =COUNTIFS(Cleaned_Futures_Data!$V$2:$V$756,$A5) -> 58 | C5: =SUMIFS(Cleaned_Futures_Data!$J$2:$J$756,Cleaned_Futures_Data!$V$2:$V$756,$A5) -> 2543096 | D5: =AVERAGEIFS(Cleaned_Futures_Data!$L$2:$L$756,Cleaned_Futures_Data!$V$2:$V$756,$A5) -> 5103951.3 | E5: =AVERAGEIFS(Cleaned_Futures_Data!$O$2:$O$756,Cleaned_Futures_Data!$V$2:$V$756,$A5) -> 170.39216 | F5: =SUMIFS(Cleaned_Futures_Data!$K$2:$K$756,Cleaned_Futures_Data!$V$2:$V$756,$A5) -> 44839197 | G5: =SUMIFS(Cleaned_Futures_Data!$J$2:$J$756,Cleaned_Futures_Data!$V$2:$V$756,$A5,Cleaned_Futures_Data!$W$2:$W$756,1) -> 2028952 | H5: =G5/C5 -> 0.79782753 | I5: =AVERAGEIFS(Cleaned_Futures_Data!$O$2:$O$756,Cleaned_Futures_Data!$V$2:$V$756,$A5,Cleaned_Futures_Data!$W$2:$W$756,1) -> 56.576471 | J5: =AVERAGEIFS(Cleaned_Futures_Data!$P$2:$P$756,Cleaned_Futures_Data!$V$2:$V$756,$A5,Cleaned_Futures_Data!$W$2:$W$756,1) -> 0.0024068558 | K5: =AVERAGEIFS(Cleaned_Futures_Data!$L$2:$L$756,Cleaned_Futures_Data!$V$2:$V$756,$A5,Cleaned_Futures_Data!$W$2:$W$756,1) -> 11641867
A6: 2025-05 | B6: =COUNTIFS(Cleaned_Futures_Data!$V$2:$V$756,$A6) -> 64 | C6: =SUMIFS(Cleaned_Futures_Data!$J$2:$J$756,Cleaned_Futures_Data!$V$2:$V$756,$A6) -> 2972628 | D6: =AVERAGEIFS(Cleaned_Futures_Data!$L$2:$L$756,Cleaned_Futures_Data!$V$2:$V$756,$A6) -> 5592363.1 | E6: =AVERAGEIFS(Cleaned_Futures_Data!$O$2:$O$756,Cleaned_Futures_Data!$V$2:$V$756,$A6) -> 160.0525 | F6: =SUMIFS(Cleaned_Futures_Data!$K$2:$K$756,Cleaned_Futures_Data!$V$2:$V$756,$A6) -> 55201331 | G6: =SUMIFS(Cleaned_Futures_Data!$J$2:$J$756,Cleaned_Futures_Data!$V$2:$V$756,$A6,Cleaned_Futures_Data!$W$2:$W$756,1) -> 2235930 | H6: =G6/C6 -> 0.75217282 | I6: =AVERAGEIFS(Cleaned_Futures_Data!$O$2:$O$756,Cleaned_Futures_Data!$V$2:$V$756,$A6,Cleaned_Futures_Data!$W$2:$W$756,1) -> 43.9075 | J6: =AVERAGEIFS(Cleaned_Futures_Data!$P$2:$P$756,Cleaned_Futures_Data!$V$2:$V$756,$A6,Cleaned_Futures_Data!$W$2:$W$756,1) -> 0.001781648 | K6: =AVERAGEIFS(Cleaned_Futures_Data!$L$2:$L$756,Cleaned_Futures_Data!$V$2:$V$756,$A6,Cleaned_Futures_Data!$W$2:$W$756,1) -> 11132689
A7: 2025-06 | B7: =COUNTIFS(Cleaned_Futures_Data!$V$2:$V$756,$A7) -> 64 | C7: =SUMIFS(Cleaned_Futures_Data!$J$2:$J$756,Cleaned_Futures_Data!$V$2:$V$756,$A7) -> 2390931 | D7: =AVERAGEIFS(Cleaned_Futures_Data!$L$2:$L$756,Cleaned_Futures_Data!$V$2:$V$756,$A7) -> 5930657.1 | E7: =AVERAGEIFS(Cleaned_Futures_Data!$O$2:$O$756,Cleaned_Futures_Data!$V$2:$V$756,$A7) -> 172.63571 | F7: =SUMIFS(Cleaned_Futures_Data!$K$2:$K$756,Cleaned_Futures_Data!$V$2:$V$756,$A7) -> 45009826 | G7: =SUMIFS(Cleaned_Futures_Data!$J$2:$J$756,Cleaned_Futures_Data!$V$2:$V$756,$A7,Cleaned_Futures_Data!$W$2:$W$756,1) -> 1771663 | H7: =G7/C7 -> 0.74099294 | I7: =AVERAGEIFS(Cleaned_Futures_Data!$O$2:$O$756,Cleaned_Futures_Data!$V$2:$V$756,$A7,Cleaned_Futures_Data!$W$2:$W$756,1) -> 55.978571 | J7: =AVERAGEIFS(Cleaned_Futures_Data!$P$2:$P$756,Cleaned_Futures_Data!$V$2:$V$756,$A7,Cleaned_Futures_Data!$W$2:$W$756,1) -> 0.002241768 | K7: =AVERAGEIFS(Cleaned_Futures_Data!$L$2:$L$756,Cleaned_Futures_Data!$V$2:$V$756,$A7,Cleaned_Futures_Data!$W$2:$W$756,1) -> 11058639
A8: 2025-07 | B8: =COUNTIFS(Cleaned_Futures_Data!$V$2:$V$756,$A8) -> 71 | C8: =SUMIFS(Cleaned_Futures_Data!$J$2:$J$756,Cleaned_Futures_Data!$V$2:$V$756,$A8) -> 1909479 | D8: =AVERAGEIFS(Cleaned_Futures_Data!$L$2:$L$756,Cleaned_Futures_Data!$V$2:$V$756,$A8) -> 6126076.1 | E8: =AVERAGEIFS(Cleaned_Futures_Data!$O$2:$O$756,Cleaned_Futures_Data!$V$2:$V$756,$A8) -> 176.39275 | F8: =SUMIFS(Cleaned_Futures_Data!$K$2:$K$756,Cleaned_Futures_Data!$V$2:$V$756,$A8) -> 36037760 | G8: =SUMIFS(Cleaned_Futures_Data!$J$2:$J$756,Cleaned_Futures_Data!$V$2:$V$756,$A8,Cleaned_Futures_Data!$W$2:$W$756,1) -> 1417569 | H8: =G8/C8 -> 0.74238523 | I8: =AVERAGEIFS(Cleaned_Futures_Data!$O$2:$O$756,Cleaned_Futures_Data!$V$2:$V$756,$A8,Cleaned_Futures_Data!$W$2:$W$756,1) -> 56.373913 | J8: =AVERAGEIFS(Cleaned_Futures_Data!$P$2:$P$756,Cleaned_Futures_Data!$V$2:$V$756,$A8,Cleaned_Futures_Data!$W$2:$W$756,1) -> 0.0022302335 | K8: =AVERAGEIFS(Cleaned_Futures_Data!$L$2:$L$756,Cleaned_Futures_Data!$V$2:$V$756,$A8,Cleaned_Futures_Data!$W$2:$W$756,1) -> 12515354
A9: 2025-08 | B9: =COUNTIFS(Cleaned_Futures_Data!$V$2:$V$756,$A9) -> 57 | C9: =SUMIFS(Cleaned_Futures_Data!$J$2:$J$756,Cleaned_Futures_Data!$V$2:$V$756,$A9) -> 1812422 | D9: =AVERAGEIFS(Cleaned_Futures_Data!$L$2:$L$756,Cleaned_Futures_Data!$V$2:$V$756,$A9) -> 6054259.2 | E9: =AVERAGEIFS(Cleaned_Futures_Data!$O$2:$O$756,Cleaned_Futures_Data!$V$2:$V$756,$A9) -> 187.67632 | F9: =SUMIFS(Cleaned_Futures_Data!$K$2:$K$756,Cleaned_Futures_Data!$V$2:$V$756,$A9) -> 33710196 | G9: =SUMIFS(Cleaned_Futures_Data!$J$2:$J$756,Cleaned_Futures_Data!$V$2:$V$756,$A9,Cleaned_Futures_Data!$W$2:$W$756,1) -> 1368990 | H9: =G9/C9 -> 0.75533733 | I9: =AVERAGEIFS(Cleaned_Futures_Data!$O$2:$O$756,Cleaned_Futures_Data!$V$2:$V$756,$A9,Cleaned_Futures_Data!$W$2:$W$756,1) -> 57.028947 | J9: =AVERAGEIFS(Cleaned_Futures_Data!$P$2:$P$756,Cleaned_Futures_Data!$V$2:$V$756,$A9,Cleaned_Futures_Data!$W$2:$W$756,1) -> 0.0023134896 | K9: =AVERAGEIFS(Cleaned_Futures_Data!$L$2:$L$756,Cleaned_Futures_Data!$V$2:$V$756,$A9,Cleaned_Futures_Data!$W$2:$W$756,1) -> 14934983
A10: 2025-09 | B10: =COUNTIFS(Cleaned_Futures_Data!$V$2:$V$756,$A10) -> 66 | C10: =SUMIFS(Cleaned_Futures_Data!$J$2:$J$756,Cleaned_Futures_Data!$V$2:$V$756,$A10) -> 1810486 | D10: =AVERAGEIFS(Cleaned_Futures_Data!$L$2:$L$756,Cleaned_Futures_Data!$V$2:$V$756,$A10) -> 6210584.1 | E10: =AVERAGEIFS(Cleaned_Futures_Data!$O$2:$O$756,Cleaned_Futures_Data!$V$2:$V$756,$A10) -> 207.24167 | F10: =SUMIFS(Cleaned_Futures_Data!$K$2:$K$756,Cleaned_Futures_Data!$V$2:$V$756,$A10) -> 33965790 | G10: =SUMIFS(Cleaned_Futures_Data!$J$2:$J$756,Cleaned_Futures_Data!$V$2:$V$756,$A10,Cleaned_Futures_Data!$W$2:$W$756,1) -> 1341682 | H10: =G10/C10 -> 0.74106179 | I10: =AVERAGEIFS(Cleaned_Futures_Data!$O$2:$O$756,Cleaned_Futures_Data!$V$2:$V$756,$A10,Cleaned_Futures_Data!$W$2:$W$756,1) -> 84.347727 | J10: =AVERAGEIFS(Cleaned_Futures_Data!$P$2:$P$756,Cleaned_Futures_Data!$V$2:$V$756,$A10,Cleaned_Futures_Data!$W$2:$W$756,1) -> 0.0033804911 | K10: =AVERAGEIFS(Cleaned_Futures_Data!$L$2:$L$756,Cleaned_Futures_Data!$V$2:$V$756,$A10,Cleaned_Futures_Data!$W$2:$W$756,1) -> 14679893
A11: 2025-10 | B11: =COUNTIFS(Cleaned_Futures_Data!$V$2:$V$756,$A11) -> 63 | C11: =SUMIFS(Cleaned_Futures_Data!$J$2:$J$756,Cleaned_Futures_Data!$V$2:$V$756,$A11) -> 2117667 | D11: =AVERAGEIFS(Cleaned_Futures_Data!$L$2:$L$756,Cleaned_Futures_Data!$V$2:$V$756,$A11) -> 6396007.3 | E11: =AVERAGEIFS(Cleaned_Futures_Data!$O$2:$O$756,Cleaned_Futures_Data!$V$2:$V$756,$A11) -> 238.49762 | F11: =SUMIFS(Cleaned_Futures_Data!$K$2:$K$756,Cleaned_Futures_Data!$V$2:$V$756,$A11) -> 40800354 | G11: =SUMIFS(Cleaned_Futures_Data!$J$2:$J$756,Cleaned_Futures_Data!$V$2:$V$756,$A11,Cleaned_Futures_Data!$W$2:$W$756,1) -> 1646457 | H11: =G11/C11 -> 0.77748626 | I11: =AVERAGEIFS(Cleaned_Futures_Data!$O$2:$O$756,Cleaned_Futures_Data!$V$2:$V$756,$A11,Cleaned_Futures_Data!$W$2:$W$756,1) -> 90.130952 | J11: =AVERAGEIFS(Cleaned_Futures_Data!$P$2:$P$756,Cleaned_Futures_Data!$V$2:$V$756,$A11,Cleaned_Futures_Data!$W$2:$W$756,1) -> 0.0035417858 | K11: =AVERAGEIFS(Cleaned_Futures_Data!$L$2:$L$756,Cleaned_Futures_Data!$V$2:$V$756,$A11,Cleaned_Futures_Data!$W$2:$W$756,1) -> 15979439
A12: 2025-11 | B12: =COUNTIFS(Cleaned_Futures_Data!$V$2:$V$756,$A12) -> 57 | C12: =SUMIFS(Cleaned_Futures_Data!$J$2:$J$756,Cleaned_Futures_Data!$V$2:$V$756,$A12) -> 1884889 | D12: =AVERAGEIFS(Cleaned_Futures_Data!$L$2:$L$756,Cleaned_Futures_Data!$V$2:$V$756,$A12) -> 6375696.5 | E12: =AVERAGEIFS(Cleaned_Futures_Data!$O$2:$O$756,Cleaned_Futures_Data!$V$2:$V$756,$A12) -> 261.53246 | F12: =SUMIFS(Cleaned_Futures_Data!$K$2:$K$756,Cleaned_Futures_Data!$V$2:$V$756,$A12) -> 36648977 | G12: =SUMIFS(Cleaned_Futures_Data!$J$2:$J$756,Cleaned_Futures_Data!$V$2:$V$756,$A12,Cleaned_Futures_Data!$W$2:$W$756,1) -> 1444775 | H12: =G12/C12 -> 0.76650402 | I12: =AVERAGEIFS(Cleaned_Futures_Data!$O$2:$O$756,Cleaned_Futures_Data!$V$2:$V$756,$A12,Cleaned_Futures_Data!$W$2:$W$756,1) -> 86.307895 | J12: =AVERAGEIFS(Cleaned_Futures_Data!$P$2:$P$756,Cleaned_Futures_Data!$V$2:$V$756,$A12,Cleaned_Futures_Data!$W$2:$W$756,1) -> 0.0033341762 | K12: =AVERAGEIFS(Cleaned_Futures_Data!$L$2:$L$756,Cleaned_Futures_Data!$V$2:$V$756,$A12,Cleaned_Futures_Data!$W$2:$W$756,1) -> 15692286
A13: 2025-12 | B13: =COUNTIFS(Cleaned_Futures_Data!$V$2:$V$756,$A13) -> 66 | C13: =SUMIFS(Cleaned_Futures_Data!$J$2:$J$756,Cleaned_Futures_Data!$V$2:$V$756,$A13) -> 1926824 | D13: =AVERAGEIFS(Cleaned_Futures_Data!$L$2:$L$756,Cleaned_Futures_Data!$V$2:$V$756,$A13) -> 5789929.4 | E13: =AVERAGEIFS(Cleaned_Futures_Data!$O$2:$O$756,Cleaned_Futures_Data!$V$2:$V$756,$A13) -> 250.17652 | F13: =SUMIFS(Cleaned_Futures_Data!$K$2:$K$756,Cleaned_Futures_Data!$V$2:$V$756,$A13) -> 36369335 | G13: =SUMIFS(Cleaned_Futures_Data!$J$2:$J$756,Cleaned_Futures_Data!$V$2:$V$756,$A13,Cleaned_Futures_Data!$W$2:$W$756,1) -> 1476951 | H13: =G13/C13 -> 0.76652097 | I13: =AVERAGEIFS(Cleaned_Futures_Data!$O$2:$O$756,Cleaned_Futures_Data!$V$2:$V$756,$A13,Cleaned_Futures_Data!$W$2:$W$756,1) -> 90.147727 | J13: =AVERAGEIFS(Cleaned_Futures_Data!$P$2:$P$756,Cleaned_Futures_Data!$V$2:$V$756,$A13,Cleaned_Futures_Data!$W$2:$W$756,1) -> 0.0034668627 | K13: =AVERAGEIFS(Cleaned_Futures_Data!$L$2:$L$756,Cleaned_Futures_Data!$V$2:$V$756,$A13,Cleaned_Futures_Data!$W$2:$W$756,1) -> 14247043
A14: Total / overall | B14: =SUM(B2:B13) -> 755 | C14: =SUM(C2:C13) -> 29854788 | F14: =SUM(F2:F13) -> 4.8299874e+08 | G14: =SUM(G2:G13) -> 23662694 | H14: =G14/C14 -> 0.79259293
A16: Months are text keys (yyyy-mm). Columns B–F use all series (as in the original workbook); columns G–K restrict to the near-month contract (Series Rank = 1). Basis averages ignore rows with no underlying value.

Sheet Expiry_Summary
A1: Expiry | B1: Observations | C1: Avg_Futures_Close | D1: Avg_Underlying | E1: Avg_Basis | F1: Avg_Basis_Pct | G1: Total_Contracts | H1: Avg_OI | I1: Max_OI | J1: Min_OI | K1: Data_Coverage
A2: 45687 | B2: =COUNTIFS(Cleaned_Futures_Data!$C$2:$C$756,$A2) -> 22 | C2: =AVERAGEIFS(Cleaned_Futures_Data!$G$2:$G$756,Cleaned_Futures_Data!$C$2:$C$756,$A2) -> 23425.048 | D2: =AVERAGEIFS(Cleaned_Futures_Data!$N$2:$N$756,Cleaned_Futures_Data!$C$2:$C$756,$A2) -> 23359.941 | E2: =AVERAGEIFS(Cleaned_Futures_Data!$O$2:$O$756,Cleaned_Futures_Data!$C$2:$C$756,$A2) -> 65.106818 | F2: =AVERAGEIFS(Cleaned_Futures_Data!$P$2:$P$756,Cleaned_Futures_Data!$C$2:$C$756,$A2) -> 0.0027724986 | G2: =SUMIFS(Cleaned_Futures_Data!$J$2:$J$756,Cleaned_Futures_Data!$C$2:$C$756,$A2) -> 5351511 | H2: =AVERAGEIFS(Cleaned_Futures_Data!$L$2:$L$756,Cleaned_Futures_Data!$C$2:$C$756,$A2) -> 12422145 | I2: =_xlfn.MAXIFS(Cleaned_Futures_Data!$L$2:$L$756,Cleaned_Futures_Data!$C$2:$C$756,$A2) -> 14572600 | J2: =_xlfn.MINIFS(Cleaned_Futures_Data!$L$2:$L$756,Cleaned_Futures_Data!$C$2:$C$756,$A2) -> 4310725 | K2: =IF($A2>Summary!$B$3,"Partial – expiry after data end",IF(_xlfn.MINIFS(Cleaned_Futures_Data!$B$2:$B$756,Cleaned_Futures_Data!$C$2:$C$756,$A2)<=Summary!$B$2,"Partial – listed before data start","Full life in data")) -> Partial – listed before data start
A3: 45715 | B3: =COUNTIFS(Cleaned_Futures_Data!$C$2:$C$756,$A3) -> 42 | C3: =AVERAGEIFS(Cleaned_Futures_Data!$G$2:$G$756,Cleaned_Futures_Data!$C$2:$C$756,$A3) -> 23384.267 | D3: =AVERAGEIFS(Cleaned_Futures_Data!$N$2:$N$756,Cleaned_Futures_Data!$C$2:$C$756,$A3) -> 23238.583 | E3: =AVERAGEIFS(Cleaned_Futures_Data!$O$2:$O$756,Cleaned_Futures_Data!$C$2:$C$756,$A3) -> 135.9 | F3: =AVERAGEIFS(Cleaned_Futures_Data!$P$2:$P$756,Cleaned_Futures_Data!$C$2:$C$756,$A3) -> 0.0058177685 | G3: =SUMIFS(Cleaned_Futures_Data!$J$2:$J$756,Cleaned_Futures_Data!$C$2:$C$756,$A3) -> 2338965 | H3: =AVERAGEIFS(Cleaned_Futures_Data!$L$2:$L$756,Cleaned_Futures_Data!$C$2:$C$756,$A3) -> 9753196.4 | I3: =_xlfn.MAXIFS(Cleaned_Futures_Data!$L$2:$L$756,Cleaned_Futures_Data!$C$2:$C$756,$A3) -> 17774775 | J3: =_xlfn.MINIFS(Cleaned_Futures_Data!$L$2:$L$756,Cleaned_Futures_Data!$C$2:$C$756,$A3) -> 1045725 | K3: =IF($A3>Summary!$B$3,"Partial – expiry after data end",IF(_xlfn.MINIFS(Cleaned_Futures_Data!$B$2:$B$756,Cleaned_Futures_Data!$C$2:$C$756,$A3)<=Summary!$B$2,"Partial – listed before data start","Full life in data")) -> Partial – listed before data start
A4: 45743 | B4: =COUNTIFS(Cleaned_Futures_Data!$C$2:$C$756,$A4) -> 61 | C4: =AVERAGEIFS(Cleaned_Futures_Data!$G$2:$G$756,Cleaned_Futures_Data!$C$2:$C$756,$A4) -> 23316.927 | D4: =AVERAGEIFS(Cleaned_Futures_Data!$N$2:$N$756,Cleaned_Futures_Data!$C$2:$C$756,$A4) -> 23092.774 | E4: =AVERAGEIFS(Cleaned_Futures_Data!$O$2:$O$756,Cleaned_Futures_Data!$C$2:$C$756,$A4) -> 214.04417 | F4: =AVERAGEIFS(Cleaned_Futures_Data!$P$2:$P$756,Cleaned_Futures_Data!$C$2:$C$756,$A4) -> 0.0092182512 | G4: =SUMIFS(Cleaned_Futures_Data!$J$2:$J$756,Cleaned_Futures_Data!$C$2:$C$756,$A4) -> 2101614 | H4: =AVERAGEIFS(Cleaned_Futures_Data!$L$2:$L$756,Cleaned_Futures_Data!$C$2:$C$756,$A4) -> 6021644.3 | I4: =_xlfn.MAXIFS(Cleaned_Futures_Data!$L$2:$L$756,Cleaned_Futures_Data!$C$2:$C$756,$A4) -> 18198750 | J4: =_xlfn.MINIFS(Cleaned_Futures_Data!$L$2:$L$756,Cleaned_Futures_Data!$C$2:$C$756,$A4) -> 126525 | K4: =IF($A4>Summary!$B$3,"Partial – expiry after data end",IF(_xlfn.MINIFS(Cleaned_Futures_Data!$B$2:$B$756,Cleaned_Futures_Data!$C$2:$C$756,$A4)<=Summary!$B$2,"Partial – listed before data start","Full life in data")) -> Partial – listed before data start
A5: 45771 | B5: =COUNTIFS(Cleaned_Futures_Data!$C$2:$C$756,$A5) -> 56 | C5: =AVERAGEIFS(Cleaned_Futures_Data!$G$2:$G$756,Cleaned_Futures_Data!$C$2:$C$756,$A5) -> 23287.536 | D5: =AVERAGEIFS(Cleaned_Futures_Data!$N$2:$N$756,Cleaned_Futures_Data!$C$2:$C$756,$A5) -> 23078.704 | E5: =AVERAGEIFS(Cleaned_Futures_Data!$O$2:$O$756,Cleaned_Futures_Data!$C$2:$C$756,$A5) -> 219.69412 | F5: =AVERAGEIFS(Cleaned_Futures_Data!$P$2:$P$756,Cleaned_Futures_Data!$C$2:$C$756,$A5) -> 0.0095708758 | G5: =SUMIFS(Cleaned_Futures_Data!$J$2:$J$756,Cleaned_Futures_Data!$C$2:$C$756,$A5) -> 2204839 | H5: =AVERAGEIFS(Cleaned_Futures_Data!$L$2:$L$756,Cleaned_Futures_Data!$C$2:$C$756,$A5) -> 4529143.6 | I5: =_xlfn.MAXIFS(Cleaned_Futures_Data!$L$2:$L$756,Cleaned_Futures_Data!$C$2:$C$756,$A5) -> 13875975 | J5: =_xlfn.MINIFS(Cleaned_Futures_Data!$L$2:$L$756,Cleaned_Futures_Data!$C$2:$C$756,$A5) -> 49125 | K5: =IF($A5>Summary!$B$3,"Partial – expiry after data end",IF(_xlfn.MINIFS(Cleaned_Futures_Data!$B$2:$B$756,Cleaned_Futures_Data!$C$2:$C$756,$A5)<=Summary!$B$2,"Partial – listed before data start","Full life in data")) -> Full life in data
A6: 45806 | B6: =COUNTIFS(Cleaned_Futures_Data!$C$2:$C$756,$A6) -> 60 | C6: =AVERAGEIFS(Cleaned_Futures_Data!$G$2:$G$756,Cleaned_Futures_Data!$C$2:$C$756,$A6) -> 23850.994 | D6: =AVERAGEIFS(Cleaned_Futures_Data!$N$2:$N$756,Cleaned_Futures_Data!$C$2:$C$756,$A6) -> 23725.772 | E6: =AVERAGEIFS(Cleaned_Futures_Data!$O$2:$O$756,Cleaned_Futures_Data!$C$2:$C$756,$A6) -> 172.98482 | F6: =AVERAGEIFS(Cleaned_Futures_Data!$P$2:$P$756,Cleaned_Futures_Data!$C$2:$C$756,$A6) -> 0.0074916305 | G6: =SUMIFS(Cleaned_Futures_Data!$J$2:$J$756,Cleaned_Futures_Data!$C$2:$C$756,$A6) -> 3092764 | H6: =AVERAGEIFS(Cleaned_Futures_Data!$L$2:$L$756,Cleaned_Futures_Data!$C$2:$C$756,$A6) -> 5760575.8 | I6: =_xlfn.MAXIFS(Cleaned_Futures_Data!$L$2:$L$756,Cleaned_Futures_Data!$C$2:$C$756,$A6) -> 13527900 | J6: =_xlfn.MINIFS(Cleaned_Futures_Data!$L$2:$L$756,Cleaned_Futures_Data!$C$2:$C$756,$A6) -> 94950 | K6: =IF($A6>Summary!$B$3,"Partial – expiry after data end",IF(_xlfn.MINIFS(Cleaned_Futures_Data!$B$2:$B$756,Cleaned_Futures_Data!$C$2:$C$756,$A6)<=Summary!$B$2,"Partial – listed before data start","Full life in data")) -> Full life in data
A7: 45834 | B7: =COUNTIFS(Cleaned_Futures_Data!$C$2:$C$756,$A7) -> 61 | C7: =AVERAGEIFS(Cleaned_Futures_Data!$G$2:$G$756,Cleaned_Futures_Data!$C$2:$C$756,$A7) -> 24534.79 | D7: =AVERAGEIFS(Cleaned_Futures_Data!$N$2:$N$756,Cleaned_Futures_Data!$C$2:$C$756,$A7) -> 24460.271 | E7: =AVERAGEIFS(Cleaned_Futures_Data!$O$2:$O$756,Cleaned_Futures_Data!$C$2:$C$756,$A7) -> 147.42054 | F7: =AVERAGEIFS(Cleaned_Futures_Data!$P$2:$P$756,Cleaned_Futures_Data!$C$2:$C$756,$A7) -> 0.0061165069 | G7: =SUMIFS(Cleaned_Futures_Data!$J$2:$J$756,Cleaned_Futures_Data!$C$2:$C$756,$A7) -> 2418474 | H7: =AVERAGEIFS(Cleaned_Futures_Data!$L$2:$L$756,Cleaned_Futures_Data!$C$2:$C$756,$A7) -> 5657630 | I7: =_xlfn.MAXIFS(Cleaned_Futures_Data!$L$2:$L$756,Cleaned_Futures_Data!$C$2:$C$756,$A7) -> 13020000 | J7: =_xlfn.MINIFS(Cleaned_Futures_Data!$L$2:$L$756,Cleaned_Futures_Data!$C$2:$C$756,$A7) -> 172650 | K7: =IF($A7>Summary!$B$3,"Partial – expiry after data end",IF(_xlfn.MINIFS(Cleaned_Futures_Data!$B$2:$B$756,Cleaned_Futures_Data!$C$2:$C$756,$A7)<=Summary!$B$2,"Partial – listed before data start","Full life in data")) -> Full life in data
A8: 45869 | B8: =COUNTIFS(Cleaned_Futures_Data!$C$2:$C$756,$A8) -> 70 | C8: =AVERAGEIFS(Cleaned_Futures_Data!$G$2:$G$756,Cleaned_Futures_Data!$C$2:$C$756,$A8) -> 25089.175 | D8: =AVERAGEIFS(Cleaned_Futures_Data!$N$2:$N$756,Cleaned_Futures_Data!$C$2:$C$756,$A8) -> 24917.006 | E8: =AVERAGEIFS(Cleaned_Futures_Data!$O$2:$O$756,Cleaned_Futures_Data!$C$2:$C$756,$A8) -> 173.44265 | F8: =AVERAGEIFS(Cleaned_Futures_Data!$P$2:$P$756,Cleaned_Futures_Data!$C$2:$C$756,$A8) -> 0.0070044582 | G8: =SUMIFS(Cleaned_Futures_Data!$J$2:$J$756,Cleaned_Futures_Data!$C$2:$C$756,$A8) -> 2223064 | H8: =AVERAGEIFS(Cleaned_Futures_Data!$L$2:$L$756,Cleaned_Futures_Data!$C$2:$C$756,$A8) -> 6670808.7 | I8: =_xlfn.MAXIFS(Cleaned_Futures_Data!$L$2:$L$756,Cleaned_Futures_Data!$C$2:$C$756,$A8) -> 14899275 | J8: =_xlfn.MINIFS(Cleaned_Futures_Data!$L$2:$L$756,Cleaned_Futures_Data!$C$2:$C$756,$A8) -> 67500 | K8: =IF($A8>Summary!$B$3,"Partial – expiry after data end",IF(_xlfn.MINIFS(Cleaned_Futures_Data!$B$2:$B$756,Cleaned_Futures_Data!$C$2:$C$756,$A8)<=Summary!$B$2,"Partial – listed before data start","Full life in data")) -> Full life in data
A9: 45897 | B9: =COUNTIFS(Cleaned_Futures_Data!$C$2:$C$756,$A9) -> 64 | C9: =AVERAGEIFS(Cleaned_Futures_Data!$G$2:$G$756,Cleaned_Futures_Data!$C$2:$C$756,$A9) -> 25145.592 | D9: =AVERAGEIFS(Cleaned_Futures_Data!$N$2:$N$756,Cleaned_Futures_Data!$C$2:$C$756,$A9) -> 24979.048 | E9: =AVERAGEIFS(Cleaned_Futures_Data!$O$2:$O$756,Cleaned_Futures_Data!$C$2:$C$756,$A9) -> 166.86048 | F9: =AVERAGEIFS(Cleaned_Futures_Data!$P$2:$P$756,Cleaned_Futures_Data!$C$2:$C$756,$A9) -> 0.0066679497 | G9: =SUMIFS(Cleaned_Futures_Data!$J$2:$J$756,Cleaned_Futures_Data!$C$2:$C$756,$A9) -> 1821835 | H9: =AVERAGEIFS(Cleaned_Futures_Data!$L$2:$L$756,Cleaned_Futures_Data!$C$2:$C$756,$A9) -> 6433994 | I9: =_xlfn.MAXIFS(Cleaned_Futures_Data!$L$2:$L$756,Cleaned_Futures_Data!$C$2:$C$756,$A9) -> 17244675 | J9: =_xlfn.MINIFS(Cleaned_Futures_Data!$L$2:$L$756,Cleaned_Futures_Data!$C$2:$C$756,$A9) -> 34575 | K9: =IF($A9>Summary!$B$3,"Partial – expiry after data end",IF(_xlfn.MINIFS(Cleaned_Futures_Data!$B$2:$B$756,Cleaned_Futures_Data!$C$2:$C$756,$A9)<=Summary!$B$2,"Partial – listed before data start","Full life in data")) -> Full life in data
A10: 45925 | B10: =COUNTIFS(Cleaned_Futures_Data!$C$2:$C$756,$A10) -> 26 | C10: =AVERAGEIFS(Cleaned_Futures_Data!$G$2:$G$756,Cleaned_Futures_Data!$C$2:$C$756,$A10) -> 25515.164 | D10: =AVERAGEIFS(Cleaned_Futures_Data!$N$2:$N$756,Cleaned_Futures_Data!$C$2:$C$756,$A10) -> 25197.894 | E10: =AVERAGEIFS(Cleaned_Futures_Data!$O$2:$O$756,Cleaned_Futures_Data!$C$2:$C$756,$A10) -> 317.27 | F10: =AVERAGEIFS(Cleaned_Futures_Data!$P$2:$P$756,Cleaned_Futures_Data!$C$2:$C$756,$A10) -> 0.012578453 | G10: =SUMIFS(Cleaned_Futures_Data!$J$2:$J$756,Cleaned_Futures_Data!$C$2:$C$756,$A10) -> 49693 | H10: =AVERAGEIFS(Cleaned_Futures_Data!$L$2:$L$756,Cleaned_Futures_Data!$C$2:$C$756,$A10) -> 414312 | I10: =_xlfn.MAXIFS(Cleaned_Futures_Data!$L$2:$L$756,Cleaned_Futures_Data!$C$2:$C$756,$A10) -> 862425 | J10: =_xlfn.MINIFS(Cleaned_Futures_Data!$L$2:$L$756,Cleaned_Futures_Data!$C$2:$C$756,$A10) -> 105225 | K10: =IF($A10>Summary!$B$3,"Partial – expiry after data end",IF(_xlfn.MINIFS(Cleaned_Futures_Data!$B$2:$B$756,Cleaned_Futures_Data!$C$2:$C$756,$A10)<=Summary!$B$2,"Partial – listed before data start","Full life in data")) -> Full life in data
A11: 45930 | B11: =COUNTIFS(Cleaned_Futures_Data!$C$2:$C$756,$A11) -> 42 | C11: =AVERAGEIFS(Cleaned_Futures_Data!$G$2:$G$756,Cleaned_Futures_Data!$C$2:$C$756,$A11) -> 24961.473 | D11: =AVERAGEIFS(Cleaned_Futures_Data!$N$2:$N$756,Cleaned_Futures_Data!$C$2:$C$756,$A11) -> 24829.337 | E11: =AVERAGEIFS(Cleaned_Futures_Data!$O$2:$O$756,Cleaned_Futures_Data!$C$2:$C$756,$A11) -> 132.13659 | F11: =AVERAGEIFS(Cleaned_Futures_Data!$P$2:$P$756,Cleaned_Futures_Data!$C$2:$C$756,$A11) -> 0.0053322058 | G11: =SUMIFS(Cleaned_Futures_Data!$J$2:$J$756,Cleaned_Futures_Data!$C$2:$C$756,$A11) -> 1804864 | H11: =AVERAGEIFS(Cleaned_Futures_Data!$L$2:$L$756,Cleaned_Futures_Data!$C$2:$C$756,$A11) -> 9609387.8 | I11: =_xlfn.MAXIFS(Cleaned_Futures_Data!$L$2:$L$756,Cleaned_Futures_Data!$C$2:$C$756,$A11) -> 17231025 | J11: =_xlfn.MINIFS(Cleaned_Futures_Data!$L$2:$L$756,Cleaned_Futures_Data!$C$2:$C$756,$A11) -> 905475 | K11: =IF($A11>Summary!$B$3,"Partial – expiry after data end",IF(_xlfn.MINIFS(Cleaned_Futures_Data!$B$2:$B$756,Cleaned_Futures_Data!$C$2:$C$756,$A11)<=Summary!$B$2,"Partial – listed before data start","Full life in data")) -> Full life in data
A12: 45958 | B12: =COUNTIFS(Cleaned_Futures_Data!$C$2:$C$756,$A12) -> 60 | C12: =AVERAGEIFS(Cleaned_Futures_Data!$G$2:$G$756,Cleaned_Futures_Data!$C$2:$C$756,$A12) -> 25211.061 | D12: =AVERAGEIFS(Cleaned_Futures_Data!$N$2:$N$756,Cleaned_Futures_Data!$C$2:$C$756,$A12) -> 25012.283 | E12: =AVERAGEIFS(Cleaned_Futures_Data!$O$2:$O$756,Cleaned_Futures_Data!$C$2:$C$756,$A12) -> 198.77797 | F12: =AVERAGEIFS(Cleaned_Futures_Data!$P$2:$P$756,Cleaned_Futures_Data!$C$2:$C$756,$A12) -> 0.0079963492 | G12: =SUMIFS(Cleaned_Futures_Data!$J$2:$J$756,Cleaned_Futures_Data!$C$2:$C$756,$A12) -> 1860756 | H12: =AVERAGEIFS(Cleaned_Futures_Data!$L$2:$L$756,Cleaned_Futures_Data!$C$2:$C$756,$A12) -> 6308780.1 | I12: =_xlfn.MAXIFS(Cleaned_Futures_Data!$L$2:$L$756,Cleaned_Futures_Data!$C$2:$C$756,$A12) -> 18296400 | J12: =_xlfn.MINIFS(Cleaned_Futures_Data!$L$2:$L$756,Cleaned_Futures_Data!$C$2:$C$756,$A12) -> 61125 | K12: =IF($A12>Summary!$B$3,"Partial – expiry after data end",IF(_xlfn.MINIFS(Cleaned_Futures_Data!$B$2:$B$756,Cleaned_Futures_Data!$C$2:$C$756,$A12)<=Summary!$B$2,"Partial – listed before data start","Full life in data")) -> Full life in data
A13: 45986 | B13: =COUNTIFS(Cleaned_Futures_Data!$C$2:$C$756,$A13) -> 60 | C13: =AVERAGEIFS(Cleaned_Futures_Data!$G$2:$G$756,Cleaned_Futures_Data!$C$2:$C$756,$A13) -> 25583.143 | D13: =AVERAGEIFS(Cleaned_Futures_Data!$N$2:$N$756,Cleaned_Futures_Data!$C$2:$C$756,$A13) -> 25365.325 | E13: =AVERAGEIFS(Cleaned_Futures_Data!$O$2:$O$756,Cleaned_Futures_Data!$C$2:$C$756,$A13) -> 217.81833 | F13: =AVERAGEIFS(Cleaned_Futures_Data!$P$2:$P$756,Cleaned_Futures_Data!$C$2:$C$756,$A13) -> 0.0086593338 | G13: =SUMIFS(Cleaned_Futures_Data!$J$2:$J$756,Cleaned_Futures_Data!$C$2:$C$756,$A13) -> 1945073 | H13: =AVERAGEIFS(Cleaned_Futures_Data!$L$2:$L$756,Cleaned_Futures_Data!$C$2:$C$756,$A13) -> 6172328.8 | I13: =_xlfn.MAXIFS(Cleaned_Futures_Data!$L$2:$L$756,Cleaned_Futures_Data!$C$2:$C$756,$A13) -> 18547500 | J13: =_xlfn.MINIFS(Cleaned_Futures_Data!$L$2:$L$756,Cleaned_Futures_Data!$C$2:$C$756,$A13) -> 47325 | K13: =IF($A13>Summary!$B$3,"Partial – expiry after data end",IF(_xlfn.MINIFS(Cleaned_Futures_Data!$B$2:$B$756,Cleaned_Futures_Data!$C$2:$C$756,$A13)<=Summary!$B$2,"Partial – listed before data start","Full life in data")) -> Full life in data
... A17: 46111 | B17: =COUNTIFS(Cleaned_Futures_Data!$C$2:$C$756,$A17) -> 1 | C17: =AVERAGEIFS(Cleaned_Futures_Data!$G$2:$G$756,Cleaned_Futures_Data!$C$2:$C$756,$A17) -> 26617.1 | D17: =AVERAGEIFS(Cleaned_Futures_Data!$N$2:$N$756,Cleaned_Futures_Data!$C$2:$C$756,$A17) -> 26129.6 | E17: =AVERAGEIFS(Cleaned_Futures_Data!$O$2:$O$756,Cleaned_Futures_Data!$C$2:$C$756,$A17) -> 487.5 | F17: =AVERAGEIFS(Cleaned_Futures_Data!$P$2:$P$756,Cleaned_Futures_Data!$C$2:$C$756,$A17) -> 0.018657002 | G17: =SUMIFS(Cleaned_Futures_Data!$J$2:$J$756,Cleaned_Futures_Data!$C$2:$C$756,$A17) -> 2553 | H17: =AVERAGEIFS(Cleaned_Futures_Data!$L$2:$L$756,Cleaned_Futures_Data!$C$2:$C$756,$A17) -> 138515 | I17: =_xlfn.MAXIFS(Cleaned_Futures_Data!$L$2:$L$756,Cleaned_Futures_Data!$C$2:$C$756,$A17) -> 138515 | J17: =_xlfn.MINIFS(Cleaned_Futures_Data!$L$2:$L$756,Cleaned_Futures_Data!$C$2:$C$756,$A17) -> 138515 | K17: =IF($A17>Summary!$B$3,"Partial – expiry after data end",IF(_xlfn.MINIFS(Cleaned_Futures_Data!$B$2:$B$756,Cleaned_Futures_Data!$C$2:$C$756,$A17)<=Summary!$B$2,"Partial – listed before data start","Full life in data")) -> Partial – expiry after data end
A19: Coverage flag: expiries listed before 01-Jan-2025 or still running after 31-Dec-2025 are only partly observed, so their averages are not comparable with full-life expiries (e.g. Mar-2026 has one row). Sep-2025 shows two expiries (25-Sep and 30-Sep) in the source data.

Sheet Basis_Analysis
A1: Basis & Rollover Analysis
A3: Expiry-week cutoff (days to expiry) | B3: 5 | C3: Input. Rows with Days to Expiry ≤ this value are treated as expiry week; the signal test on the OI_Interpretation_Summary sheet excludes them because OI falls mechanically as contracts expire.
A4: Near-month annualised basis (DTE > cutoff) | B4: =AVERAGEIFS(Cleaned_Futures_Data!$X$2:$X$756,Cleaned_Futures_Data!$W$2:$W$756,1,Cleaned_Futures_Data!$Q$2:$Q$756,">"&B3) -> 0.069360256 | C4: Annualised basis = Basis % × 365 ÷ Days to Expiry: the carry rate implied by the futures price. No interest-rate or dividend data was supplied, so it is not benchmarked here.
A6: 1. Near-month basis by days to expiry
A7: Days-to-expiry bucket | B7: From (DTE) | C7: To (DTE) | D7: Observations | E7: Avg Basis (pts) | F7: Avg Basis % | G7: Avg Annualised Basis % | H7: Avg Near-Month OI | I7: Avg Next-Month OI | J7: Near-Month Share of Near+Next OI
A8: Expiry day (0) | B8: 0 | C8: 0 | D8: =COUNTIFS(Cleaned_Futures_Data!$W$2:$W$756,1,Cleaned_Futures_Data!$Q$2:$Q$756,">="&$B8,Cleaned_Futures_Data!$Q$2:$Q$756,"<="&$C8) -> 12 | E8: =IFERROR(AVERAGEIFS(Cleaned_Futures_Data!$O$2:$O$756,Cleaned_Futures_Data!$W$2:$W$756,1,Cleaned_Futures_Data!$Q$2:$Q$756,">="&$B8,Cleaned_Futures_Data!$Q$2:$Q$756,"<="&$C8),"") -> -3.5375 | F8: =IFERROR(AVERAGEIFS(Cleaned_Futures_Data!$P$2:$P$756,Cleaned_Futures_Data!$W$2:$W$756,1,Cleaned_Futures_Data!$Q$2:$Q$756,">="&$B8,Cleaned_Futures_Data!$Q$2:$Q$756,"<="&$C8),"") -> -0.00014296025 | G8: =IFERROR(AVERAGEIFS(Cleaned_Futures_Data!$X$2:$X$756,Cleaned_Futures_Data!$W$2:$W$756,1,Cleaned_Futures_Data!$Q$2:$Q$756,">="&$B8,Cleaned_Futures_Data!$Q$2:$Q$756,"<="&$C8),"") | H8: =IFERROR(AVERAGEIFS(Cleaned_Futures_Data!$L$2:$L$756,Cleaned_Futures_Data!$W$2:$W$756,1,Cleaned_Futures_Data!$Q$2:$Q$756,">="&$B8,Cleaned_Futures_Data!$Q$2:$Q$756,"<="&$C8),"") -> 4449502.1 | I8: =IFERROR(AVERAGEIFS(Cleaned_Futures_Data!$AA$2:$AA$756,Cleaned_Futures_Data!$W$2:$W$756,1,Cleaned_Futures_Data!$Q$2:$Q$756,">="&$B8,Cleaned_Futures_Data!$Q$2:$Q$756,"<="&$C8),"") -> 14677926 | J8: =IFERROR(AVERAGEIFS(Cleaned_Futures_Data!$AB$2:$AB$756,Cleaned_Futures_Data!$W$2:$W$756,1,Cleaned_Futures_Data!$Q$2:$Q$756,">="&$B8,Cleaned_Futures_Data!$Q$2:$Q$756,"<="&$C8),"") -> 0.23318386
A9: 1–5 days | B9: 1 | C9: 5 | D9: =COUNTIFS(Cleaned_Futures_Data!$W$2:$W$756,1,Cleaned_Futures_Data!$Q$2:$Q$756,">="&$B9,Cleaned_Futures_Data!$Q$2:$Q$756,"<="&$C9) -> 33 | E9: =IFERROR(AVERAGEIFS(Cleaned_Futures_Data!$O$2:$O$756,Cleaned_Futures_Data!$W$2:$W$756,1,Cleaned_Futures_Data!$Q$2:$Q$756,">="&$B9,Cleaned_Futures_Data!$Q$2:$Q$756,"<="&$C9),"") -> 26.9 | F9: =IFERROR(AVERAGEIFS(Cleaned_Futures_Data!$P$2:$P$756,Cleaned_Futures_Data!$W$2:$W$756,1,Cleaned_Futures_Data!$Q$2:$Q$756,">="&$B9,Cleaned_Futures_Data!$Q$2:$Q$756,"<="&$C9),"") -> 0.0010907241 | G9: =IFERROR(AVERAGEIFS(Cleaned_Futures_Data!$X$2:$X$756,Cleaned_Futures_Data!$W$2:$W$756,1,Cleaned_Futures_Data!$Q$2:$Q$756,">="&$B9,Cleaned_Futures_Data!$Q$2:$Q$756,"<="&$C9),"") -> 0.18762342 | H9: =IFERROR(AVERAGEIFS(Cleaned_Futures_Data!$L$2:$L$756,Cleaned_Futures_Data!$W$2:$W$756,1,Cleaned_Futures_Data!$Q$2:$Q$756,">="&$B9,Cleaned_Futures_Data!$Q$2:$Q$756,"<="&$C9),"") -> 9486627.3 | I9: =IFERROR(AVERAGEIFS(Cleaned_Futures_Data!$AA$2:$AA$756,Cleaned_Futures_Data!$W$2:$W$756,1,Cleaned_Futures_Data!$Q$2:$Q$756,">="&$B9,Cleaned_Futures_Data!$Q$2:$Q$756,"<="&$C9),"") -> 8951233.6 | J9: =IFERROR(AVERAGEIFS(Cleaned_Futures_Data!$AB$2:$AB$756,Cleaned_Futures_Data!$W$2:$W$756,1,Cleaned_Futures_Data!$Q$2:$Q$756,">="&$B9,Cleaned_Futures_Data!$Q$2:$Q$756,"<="&$C9),"") -> 0.51673281
A10: 6–10 days | B10: 6 | C10: 10 | D10: =COUNTIFS(Cleaned_Futures_Data!$W$2:$W$756,1,Cleaned_Futures_Data!$Q$2:$Q$756,">="&$B10,Cleaned_Futures_Data!$Q$2:$Q$756,"<="&$C10) -> 49 | E10: =IFERROR(AVERAGEIFS(Cleaned_Futures_Data!$O$2:$O$756,Cleaned_Futures_Data!$W$2:$W$756,1,Cleaned_Futures_Data!$Q$2:$Q$756,">="&$B10,Cleaned_Futures_Data!$Q$2:$Q$756,"<="&$C10),"") -> 38.687755 | F10: =IFERROR(AVERAGEIFS(Cleaned_Futures_Data!$P$2:$P$756,Cleaned_Futures_Data!$W$2:$W$756,1,Cleaned_Futures_Data!$Q$2:$Q$756,">="&$B10,Cleaned_Futures_Data!$Q$2:$Q$756,"<="&$C10),"") -> 0.0015886367 | G10: =IFERROR(AVERAGEIFS(Cleaned_Futures_Data!$X$2:$X$756,Cleaned_Futures_Data!$W$2:$W$756,1,Cleaned_Futures_Data!$Q$2:$Q$756,">="&$B10,Cleaned_Futures_Data!$Q$2:$Q$756,"<="&$C10),"") -> 0.073096908 | H10: =IFERROR(AVERAGEIFS(Cleaned_Futures_Data!$L$2:$L$756,Cleaned_Futures_Data!$W$2:$W$756,1,Cleaned_Futures_Data!$Q$2:$Q$756,">="&$B10,Cleaned_Futures_Data!$Q$2:$Q$756,"<="&$C10),"") -> 14117129 | I10: =IFERROR(AVERAGEIFS(Cleaned_Futures_Data!$AA$2:$AA$756,Cleaned_Futures_Data!$W$2:$W$756,1,Cleaned_Futures_Data!$Q$2:$Q$756,">="&$B10,Cleaned_Futures_Data!$Q$2:$Q$756,"<="&$C10),"") -> 3889119.5 | J10: =IFERROR(AVERAGEIFS(Cleaned_Futures_Data!$AB$2:$AB$756,Cleaned_Futures_Data!$W$2:$W$756,1,Cleaned_Futures_Data!$Q$2:$Q$756,">="&$B10,Cleaned_Futures_Data!$Q$2:$Q$756,"<="&$C10),"") -> 0.78422123
A11: 11–15 days | B11: 11 | C11: 15 | D11: =COUNTIFS(Cleaned_Futures_Data!$W$2:$W$756,1,Cleaned_Futures_Data!$Q$2:$Q$756,">="&$B11,Cleaned_Futures_Data!$Q$2:$Q$756,"<="&$C11) -> 41 | E11: =IFERROR(AVERAGEIFS(Cleaned_Futures_Data!$O$2:$O$756,Cleaned_Futures_Data!$W$2:$W$756,1,Cleaned_Futures_Data!$Q$2:$Q$756,">="&$B11,Cleaned_Futures_Data!$Q$2:$Q$756,"<="&$C11),"") -> 70.434146 | F11: =IFERROR(AVERAGEIFS(Cleaned_Futures_Data!$P$2:$P$756,Cleaned_Futures_Data!$W$2:$W$756,1,Cleaned_Futures_Data!$Q$2:$Q$756,">="&$B11,Cleaned_Futures_Data!$Q$2:$Q$756,"<="&$C11),"") -> 0.002845293 | G11: =IFERROR(AVERAGEIFS(Cleaned_Futures_Data!$X$2:$X$756,Cleaned_Futures_Data!$W$2:$W$756,1,Cleaned_Futures_Data!$Q$2:$Q$756,">="&$B11,Cleaned_Futures_Data!$Q$2:$Q$756,"<="&$C11),"") -> 0.07691491 | H11: =IFERROR(AVERAGEIFS(Cleaned_Futures_Data!$L$2:$L$756,Cleaned_Futures_Data!$W$2:$W$756,1,Cleaned_Futures_Data!$Q$2:$Q$756,">="&$B11,Cleaned_Futures_Data!$Q$2:$Q$756,"<="&$C11),"") -> 15523145 | I11: =IFERROR(AVERAGEIFS(Cleaned_Futures_Data!$AA$2:$AA$756,Cleaned_Futures_Data!$W$2:$W$756,1,Cleaned_Futures_Data!$Q$2:$Q$756,">="&$B11,Cleaned_Futures_Data!$Q$2:$Q$756,"<="&$C11),"") -> 2414347.9 | J11: =IFERROR(AVERAGEIFS(Cleaned_Futures_Data!$AB$2:$AB$756,Cleaned_Futures_Data!$W$2:$W$756,1,Cleaned_Futures_Data!$Q$2:$Q$756,">="&$B11,Cleaned_Futures_Data!$Q$2:$Q$756,"<="&$C11),"") -> 0.86295531
A12: 16–20 days | B12: 16 | C12: 20 | D12: =COUNTIFS(Cleaned_Futures_Data!$W$2:$W$756,1,Cleaned_Futures_Data!$Q$2:$Q$756,">="&$B12,Cleaned_Futures_Data!$Q$2:$Q$756,"<="&$C12) -> 35 | E12: =IFERROR(AVERAGEIFS(Cleaned_Futures_Data!$O$2:$O$756,Cleaned_Futures_Data!$W$2:$W$756,1,Cleaned_Futures_Data!$Q$2:$Q$756,">="&$B12,Cleaned_Futures_Data!$Q$2:$Q$756,"<="&$C12),"") -> 82.492424 | F12: =IFERROR(AVERAGEIFS(Cleaned_Futures_Data!$P$2:$P$756,Cleaned_Futures_Data!$W$2:$W$756,1,Cleaned_Futures_Data!$Q$2:$Q$756,">="&$B12,Cleaned_Futures_Data!$Q$2:$Q$756,"<="&$C12),"") -> 0.0033622228 | G12: =IFERROR(AVERAGEIFS(Cleaned_Futures_Data!$X$2:$X$756,Cleaned_Futures_Data!$W$2:$W$756,1,Cleaned_Futures_Data!$Q$2:$Q$756,">="&$B12,Cleaned_Futures_Data!$Q$2:$Q$756,"<="&$C12),"") -> 0.067884369 | H12: =IFERROR(AVERAGEIFS(Cleaned_Futures_Data!$L$2:$L$756,Cleaned_Futures_Data!$W$2:$W$756,1,Cleaned_Futures_Data!$Q$2:$Q$756,">="&$B12,Cleaned_Futures_Data!$Q$2:$Q$756,"<="&$C12),"") -> 15449382 | I12: =IFERROR(AVERAGEIFS(Cleaned_Futures_Data!$AA$2:$AA$756,Cleaned_Futures_Data!$W$2:$W$756,1,Cleaned_Futures_Data!$Q$2:$Q$756,">="&$B12,Cleaned_Futures_Data!$Q$2:$Q$756,"<="&$C12),"") -> 2086922.9 | J12: =IFERROR(AVERAGEIFS(Cleaned_Futures_Data!$AB$2:$AB$756,Cleaned_Futures_Data!$W$2:$W$756,1,Cleaned_Futures_Data!$Q$2:$Q$756,">="&$B12,Cleaned_Futures_Data!$Q$2:$Q$756,"<="&$C12),"") -> 0.8786989
A13: 21+ days | B13: 21 | C13: 60 | D13: =COUNTIFS(Cleaned_Futures_Data!$W$2:$W$756,1,Cleaned_Futures_Data!$Q$2:$Q$756,">="&$B13,Cleaned_Futures_Data!$Q$2:$Q$756,"<="&$C13) -> 79 | E13: =IFERROR(AVERAGEIFS(Cleaned_Futures_Data!$O$2:$O$756,Cleaned_Futures_Data!$W$2:$W$756,1,Cleaned_Futures_Data!$Q$2:$Q$756,">="&$B13,Cleaned_Futures_Data!$Q$2:$Q$756,"<="&$C13),"") -> 108.64539 | F13: =IFERROR(AVERAGEIFS(Cleaned_Futures_Data!$P$2:$P$756,Cleaned_Futures_Data!$W$2:$W$756,1,Cleaned_Futures_Data!$Q$2:$Q$756,">="&$B13,Cleaned_Futures_Data!$Q$2:$Q$756,"<="&$C13),"") -> 0.0043944588 | G13: =IFERROR(AVERAGEIFS(Cleaned_Futures_Data!$X$2:$X$756,Cleaned_Futures_Data!$W$2:$W$756,1,Cleaned_Futures_Data!$Q$2:$Q$756,">="&$B13,Cleaned_Futures_Data!$Q$2:$Q$756,"<="&$C13),"") -> 0.063516408 | H13: =IFERROR(AVERAGEIFS(Cleaned_Futures_Data!$L$2:$L$756,Cleaned_Futures_Data!$W$2:$W$756,1,Cleaned_Futures_Data!$Q$2:$Q$756,">="&$B13,Cleaned_Futures_Data!$Q$2:$Q$756,"<="&$C13),"") -> 14995779 | I13: =IFERROR(AVERAGEIFS(Cleaned_Futures_Data!$AA$2:$AA$756,Cleaned_Futures_Data!$W$2:$W$756,1,Cleaned_Futures_Data!$Q$2:$Q$756,">="&$B13,Cleaned_Futures_Data!$Q$2:$Q$756,"<="&$C13),"") -> 1469833.2 | J13: =IFERROR(AVERAGEIFS(Cleaned_Futures_Data!$AB$2:$AB$756,Cleaned_Futures_Data!$W$2:$W$756,1,Cleaned_Futures_Data!$Q$2:$Q$756,">="&$B13,Cleaned_Futures_Data!$Q$2:$Q$756,"<="&$C13),"") -> 0.90931415
A14: Note: annualising very short tenors (≤5 days) is noisy because a small basis is divided by a small number of days. Near-month OI share = average of the daily ratio OI(near) ÷ [OI(near)+OI(next)].
A16: 2. Basis and liquidity by contract series
A17: Series | B17: Rank from | C17: Rank to | D17: Observations | E17: Total Contracts | F17: Share of Contracts | G17: Avg Open Interest | H17: Avg Basis (pts) | I17: Avg Basis %
